Workbook

Sheet Instructions
A1: Excel Practical Project: Sales, Customer & Order Management Analysis
A3: Welcome & Course Overview
A4: Target Audience: | B4: Beginner to Intermediate students learning Excel for office work, data analysis, and career development.
A5: Workbook Structure: | B5: This workbook consists of 9 structured sheets covering end-to-end data processing, practical analysis, and visual dashboarding.
A7: Sheet Descriptions & Workflow:
A8: 1. Instructions | B8: Project overview, key concepts, learning objectives, and guidance for students.
A9: 2. Sales_Data | B9: Master raw dataset containing 100+ realistic Indian retail/wholesale transactions. Used for sorting, filtering, formulas, and conditional formatting.
A10: 3. Data_Entry | B10: An interactive Order Entry Template incorporating Data Validation rules (drop-downs, range constraints, custom alert messages).
A11: 4. Series_Practice | B11: Practical exercises for generating Linear, Growth, Date, Weekday, Month, and Custom AutoFill series.
A12: 5. Analysis | B12: Calculated summary metrics using basic (SUM, AVERAGE, MIN, MAX) and conditional statistical functions (COUNT, COUNTA, COUNTIF, SUMIF, AVERAGEIF).
A13: 6. Date_Practice | B13: Exercises focused on Date & Time operations (TODAY, YEAR, MONTH, DAY, WEEKDAY, DATEDIF, EOMONTH, delivery duration calculations).
A14: 7. Text_Practice | B14: Data cleaning and string manipulation exercises (TRIM, PROPER, LEFT, RIGHT, MID, CONCAT, TEXTJOIN, SUBSTITUTE, SEARCH).
A15: 8. Dashboard | B15: Executive KPI summary cards and visual interactive charts summarizing Sales by Category, City, Salesperson, and Order Status.
A16: 9. Final_Challenge | B16: Independent final assessment containing 10 business problem statements designed to test real-world proficiency.

Sheet Sales_Data
A1: Order_ID | B1: Order_Date | C1: Customer_Name | D1: Gender | E1: Age | F1: City | G1: State | H1: Product_Category | I1: Product | J1: Salesperson | K1: Quantity | L1: Unit_Price | M1: Discount | N1: Payment_Mode | O1: Order_Status | P1: Delivery_Date | Q1: Rating | R1: Customer_Type | S1: Remarks | T1: Total_Amount | U1: Discount_Amount | V1: Net_Sales
A2: ORD-1001 | B2: 46186 | C2: Aarav Shah | D2: Female | E2: 36 | F2: Pune | G2: Maharashtra | H2: Electronics | I2: Laptop | J2: Neha Gupta | K2: 24 | L2: 55000 | M2: 0.2 | N2: Cash | O2: Completed | P2: 46187 | Q2: 1 | R2: New | S2: Prompt delivery requested | T2: =K2*L2 -> 1320000 | U2: =T2*M2 -> 264000 | V2: =T2-U2 -> 1056000
A3: ORD-1002 | B3: 46078 | C3: Vivaan Gaikwad | D3: Male | E3: 56 | F3: Pune | G3: Maharashtra | H3: Accessories | I3: USB Cable | J3: Sneha Kulkarni | K3: 8 | L3: 250 | M3: 0.15 | N3: Net Banking | O3: Completed | P3: 46080 | Q3: 1 | R3: New | S3: Satisfied with service | T3: =K3*L3 -> 2000 | U3: =T3*M3 -> 300 | V3: =T3-U3 -> 1700
A4: ORD-1003 | B4: 46131 | C4: Arjun Nair | D4: Male | E4: 34 | F4: Chennai | G4: Tamil Nadu | H4: Office Supplies | I4: Notebook | J4: Amit Sharma | K4: 13 | L4: 150 | M4: 0 | N4: Credit Card | O4: Pending | P4: 46134 | Q4: 5 | R4: Returning | S4: Follow up needed | T4: =K4*L4 -> 1950 | U4: =T4*M4 -> 0 | V4: =T4-U4 -> 1950
A5: ORD-1004 | B5: 46034 | C5: Reyansh Bhat | D5: Male | E5: 45 | F5: Nashik | G5: Maharashtra | H5: Accessories | I5: USB Drive | J5: Rajesh Khan | K5: 21 | L5: 750 | M5: 0.2 | N5: Credit Card | O5: Completed | P5: 46040 | Q5: 1 | R5: New | S5: Satisfied with service | T5: =K5*L5 -> 15750 | U5: =T5*M5 -> 3150 | V5: =T5-U5 -> 12600
A6: ORD-1005 | B6: 46081 | C6: Sanya Iyer | D6: Male | E6: 35 | F6: Nashik | G6: Maharashtra | H6: Office Supplies | I6: File Folder | J6: Sneha Kulkarni | K6: 21 | L6: 85 | M6: 0.1 | N6: UPI | O6: Completed | P6: 46088 | Q6: 2 | R6: Returning | S6: Satisfied with service | T6: =K6*L6 -> 1785 | U6: =T6*M6 -> 178.5 | V6: =T6-U6 -> 1606.5
A7: ORD-1006 | B7: 46262 | C7: Omkar Salunkhe | D7: Male | E7: 59 | F7: Bengaluru | G7: Karnataka | H7: Electronics | I7: Printer | J7: Neha Gupta | K7: 8 | L7: 12500 | M7: 0.05 | N7: Debit Card | O7: Completed | P7: 46268 | Q7: 5 | R7: New | S7: Satisfied with service | T7: =K7*L7 -> 100000 | U7: =T7*M7 -> 5000 | V7: =T7-U7 -> 95000
A8: ORD-1007 | B8: 46106 | C8: Yash Borse | D8: Male | E8: 35 | F8: Malegaon | G8: Maharashtra | H8: Office Supplies | I8: Calculator | J8: Rahul Verma | K8: 3 | L8: 450 | M8: 0.05 | N8: Net Banking | O8: Pending | P8: 46113 | Q8: 3 | R8: New | S8: Satisfied with service | T8: =K8*L8 -> 1350 | U8: =T8*M8 -> 67.5 | V8: =T8-U8 -> 1282.5
A9: ORD-1008 | B9: 46150 | C9: Omkar Salunkhe | D9: Female | E9: 30 | F9: Nagpur | G9: Maharashtra | H9: Electronics | I9: Keyboard | J9: Neha Gupta | K9: 18 | L9: 1200 | M9: 0.2 | N9: Credit Card | O9: Pending | P9: 46154 | Q9: 4 | R9: Returning | S9: Gift wrap required | T9: =K9*L9 -> 21600 | U9: =T9*M9 -> 4320 | V9: =T9-U9 -> 17280
A10: ORD-1009 | B10: 46079 | C10: Vivaan Gaikwad | D10: Female | E10: 26 | F10: Chennai | G10: Tamil Nadu | H10: Electronics | I10: Laptop | J10: Priya Patel | K10: 21 | L10: 55000 | M10: 0.05 | N10: Debit Card | O10: Completed | P10: 46081 | Q10: 4 | R10: Returning | S10: Standard packing | T10: =K10*L10 -> 1155000 | U10: =T10*M10 -> 57750 | V10: =T10-U10 -> 1097250
A11: ORD-1010 | B11: 46142 | C11: Arjun Nair | D11: Male | E11: 28 | F11: Bengaluru | G11: Karnataka | H11: Accessories | I11: USB Drive | J11: Rajesh Khan | K11: 21 | L11: 750 | M11: 0.1 | N11: Cash | O11: Completed | P11: 46147 | Q11: 2 | R11: Returning | S11: Prompt delivery requested | T11: =K11*L11 -> 15750 | U11: =T11*M11 -> 1575 | V11: =T11-U11 -> 14175
A12: ORD-1011 | B12: 46207 | C12: Arjun Nair | D12: Male | E12: 53 | F12: Nashik | G12: Maharashtra | H12: Accessories | I12: USB Drive | J12: Rajesh Khan | K12: 21 | L12: 750 | M12: 0.2 | N12: Net Banking | O12: Completed | P12: 46213 | Q12: 3 | R12: New | S12: Standard packing | T12: =K12*L12 -> 15750 | U12: =T12*M12 -> 3150 | V12: =T12-U12 -> 12600
A13: ORD-1012 | B13: 46222 | C13: aarav shah | D13: Female | E13: 52 | F13: Malegaon | G13: Maharashtra | H13: Electronics | I13: Mouse | J13: Rajesh Khan | K13: 10 | L13: 650 | M13: 0.05 | N13: Cash | O13: Completed | P13: 46227 | Q13: 5 | R13: New | S13: Prompt delivery requested | T13: =K13*L13 -> 6500 | U13: =T13*M13 -> 325 | V13: =T13-U13 -> 6175
... A15: ORD-1014 | B15: 46102 | C15: Tanvi Nikam | D15: Female | E15: 49 | F15: Ahmednagar | G15: Maharashtra | H15: Office Supplies | I15: Notebook | J15: Priya Patel | K15: 8 | L15: 150 | M15: 0 | N15: Credit Card | O15: Completed | P15: 46106 | Q15: 5 | R15: New | S15: Standard packing | T15: =K15*L15 -> 1200 | U15: =T15*M15 -> 0 | V15: =T15-U15 -> 1200
A16: ORD-1015 | B16: 46079 | C16: Rohan Joshi | D16: Male | E16: 35 | F16: Nashik | G16: Maharashtra | H16: Electronics | I16: Mouse | J16: Amit Sharma | K16: 17 | L16: 650 | M16: 0.05 | N16: Credit Card | O16: Completed | P16: 46080 | R16: New | S16: Satisfied with service | T16: =K16*L16 -> 11050 | U16: =T16*M16 -> 552.5 | V16: =T16-U16 -> 10497.5
A17: ORD-1016 | B17: 46262 | C17: Dhruv Sawant | D17: Female | E17: 36 | F17: Chennai | G17: Tamil Nadu | H17: Office Supplies | I17: Calculator | J17: Priya Patel | K17: 4 | L17: 450 | M17: 0 | N17: Debit Card | O17: Completed | P17: 46267 | Q17: 4 | R17: Returning | S17: Follow up needed | T17: =K17*L17 -> 1800 | U17: =T17*M17 -> 0 | V17: =T17-U17 -> 1800
A18: ORD-1017 | B18: 46209 | C18: Tanvi Nikam | D18: Male | E18: 24 | F18: Jalgaon | G18: Maharashtra | H18: Accessories | I18: USB Drive | J18: Rajesh Khan | K18: 4 | L18: 750 | M18: 0.05 | N18: UPI | O18: Completed | P18: 46210 | Q18: 4 | R18: New | S18: Call before delivery | T18: =K18*L18 -> 3000 | U18: =T18*M18 -> 150 | V18: =T18-U18 -> 2850
A19: ORD-1018 | B19: 46069 | C19: Reyansh Bhat | D19: Male | E19: 25 | F19: Dhule | G19: Maharashtra | H19: Accessories | I19: Headphones | J19: Amit Sharma | K19: 21 | L19: 2200 | M19: 0.2 | N19: Cash | O19: Cancelled | P19: 46072 | Q19: 2 | R19: New | S19: Call before delivery | T19: =K19*L19 -> 46200 | U19: =T19*M19 -> 9240 | V19: =T19-U19 -> 36960
A20: ORD-1019 | B20: 46147 | C20: Kabir Kulkarni | D20: Female | E20: 24 | F20: Mumbai | G20: Maharashtra | H20: Office Supplies | I20: Notebook | J20: Sneha Kulkarni | K20: 9 | L20: 150 | M20: 0.15 | N20: Credit Card | O20: Completed | P20: 46151 | Q20: 5 | R20: Returning | S20: Handle with care | T20: =K20*L20 -> 1350 | U20: =T20*M20 -> 202.5 | V20: =T20-U20 -> 1147.5
A21: ORD-1020 | B21: 46071 | C21: Kabir Kulkarni | D21: Male | E21: 58 | F21: Hyderabad | G21: Telangana | H21: Accessories | I21: Headphones | J21: Neha Gupta | K21: 11 | L21: 2200 | M21: 0 | N21: Cash | O21: Completed | P21: 46074 | Q21: 5 | R21: New | S21: Prompt delivery requested | T21: =K21*L21 -> 24200 | U21: =T21*M21 -> 0 | V21: =T21-U21 -> 24200
A22: ORD-1021 | B22: 46153 | C22: Isha Mehta | D22: Male | E22: 59 | F22: Nashik | G22: Maharashtra | H22: Accessories | I22: Webcam | J22: Sneha Kulkarni | K22: 4 | L22: 3500 | M22: 0.2 | N22: UPI | O22: Completed | P22: 46154 | Q22: 1 | R22: New | S22: Call before delivery | T22: =K22*L22 -> 14000 | U22: =T22*M22 -> 2800 | V22: =T22-U22 -> 11200
A23: ORD-1022 | B23: 46191 | C23: Dhruv Sawant | D23: Female | E23: 37 | F23: Pune | G23: Maharashtra | H23: Accessories | I23: USB Drive | J23: Priya Patel | K23: 9 | L23: 750 | M23: 0.15 | N23: UPI | O23: Completed | P23: 46196 | Q23: 3 | R23: Returning | S23: Gift wrap required | T23: =K23*L23 -> 6750 | U23: =T23*M23 -> 1012.5 | V23: =T23-U23 -> 5737.5
A24: ORD-1023 | B24: 46260 | C24: Rohan Joshi | D24: Male | E24: 50 | F24: Delhi | G24: Delhi | H24: Accessories | I24: Headphones | J24: Amit Sharma | K24: 18 | L24: 2200 | M24: 0.05 | N24: Net Banking | O24: Completed | P24: 46267 | Q24: 3 | R24: New | S24: Handle with care | T24: =K24*L24 -> 39600 | U24: =T24*M24 -> 1980 | V24: =T24-U24 -> 37620
A25: ORD-1024 | B25: 46117 | C25: Isha Mehta | D25: Female | E25: 55 | F25: Hyderabad | G25: Telangana | H25: Office Supplies | I25: Printer Paper | J25: Rajesh Khan | K25: 21 | L25: 320 | M25: 0.2 | N25: Cash | O25: Completed | P25: 46120 | Q25: 5 | R25: Returning | S25: Satisfied with service | T25: =K25*L25 -> 6720 | U25: =T25*M25 -> 1344 | V25: =T25-U25 -> 5376
A26: ORD-1024 | B26: 46049 | C26: Arjun Nair | D26: Male | E26: 27 | F26: Hyderabad | G26: Telangana | H26: Accessories | I26: Webcam | J26: Rahul Verma | K26: 10 | L26: 3500 | M26: 0.2 | N26: UPI | O26: Pending | P26: 46051 | Q26: 2 | R26: Returning | S26: Standard packing | T26: =K26*L26 -> 35000 | U26: =T26*M26 -> 7000 | V26: =T26-U26 -> 28000
A27: ORD-1026 | B27: 46148 | C27: Aditi Deshmukh | D27: Male | E27: 61 | F27: Jalgaon | G27: Maharashtra | H27: Office Supplies | I27: Notebook | J27: Amit Sharma | K27: 11 | L27: 150 | M27: 0.05 | N27: Credit Card | O27: Completed | P27: 46151 | Q27: 4 | R27: Returning | S27: Standard packing | T27: =K27*L27 -> 1650 | U27: =T27*M27 -> 82.5 | V27: =T27-U27 -> 1567.5
A28: ORD-1027 | B28: 46025 | C28: Rohan Joshi | D28: Male | E28: 55 | F28: Malegaon | G28: Maharashtra | H28: Office Supplies | I28: Printer Paper | J28: Vikas Rao | K28: 5 | L28: 320 | M28: 0.15 | N28: UPI | O28: Completed | P28: 46026 | Q28: 3 | R28: New | S28: Gift wrap required | T28: =K28*L28 -> 1600 | U28: =T28*M28 -> 240 | V28: =T28-U28 -> 1360
... A42: ORD-1041 | B42: 46077 | C42: Kiara Wagh | D42: Female | E42: 42 | F42: Ahmednagar | G42: Maharashtra | H42: Office Supplies | I42: Calculator | J42: Amit Sharma | K42: 7 | L42: 450 | M42: 0.15 | N42: Debit Card | O42: Cancelled | P42: 46078 | Q42: 5 | R42: New | S42: Follow up needed | T42: =K42*L42 -> 3150 | U42: =T42*M42 -> 472.5 | V42: =T42-U42 -> 2677.5
A43: ORD-1042 | B43: 46248 | C43: Dhruv Sawant | D43: Female | E43: 51 | F43: Malegaon | G43: Maharashtra | H43: Office Supplies | I43: File Folder | J43: Rajesh Khan | K43: 13 | L43: 85 | M43: 0.15 | N43: Net Banking | O43: Pending | P43: 46255 | Q43: 5 | R43: New | T43: =K43*L43 -> 1105 | U43: =T43*M43 -> 165.75 | V43: =T43-U43 -> 939.25
A44: ORD-1043 | B44: 46079 | C44: Kiara Wagh | D44: Female | E44: 22 | F44: Jalgaon | G44: Maharashtra | H44: Office Supplies | I44: Calculator | J44: Neha Gupta | K44: 6 | L44: 450 | M44: 0.15 | N44: UPI | O44: Cancelled | P44: 46082 | Q44: 5 | R44: New | S44: Call before delivery | T44: =K44*L44 -> 2700 | U44: =T44*M44 -> 405 | V44: =T44-U44 -> 2295
A45: ORD-1044 | B45: 46174 | C45: Tanvi Nikam | D45: Male | E45: 26 | F45: Bengaluru | G45: Karnataka | H45: Office Supplies | I45: Pen | J45: Rajesh Khan | K45: 15 | L45: 45 | M45: 0.05 | N45: Cash | O45: Completed | P45: 46179 | Q45: 3 | R45: New | S45: Call before delivery | T45: =K45*L45 -> 675 | U45: =T45*M45 -> 33.75 | V45: =T45-U45 -> 641.25
A46: ORD-1045 | B46: 46106 | C46: Yash Borse | D46: Female | E46: 38 | F46: Chennai | G46: Tamil Nadu | H46: Office Supplies | I46: File Folder | J46: Rajesh Khan | K46: 3 | L46: 85 | M46: 0.15 | N46: Cash | O46: Pending | P46: 46109 | Q46: 1 | R46: Returning | S46: Handle with care | T46: =K46*L46 -> 255 | U46: =T46*M46 -> 38.25 | V46: =T46-U46 -> 216.75
A47: ORD-1046 | B47: 46189 | C47: Yash Borse | D47: Male | E47: 22 | F47: Pune | G47: Maharashtra | H47: Electronics | I47: Laptop | J47: Vikas Rao | K47: 5 | L47: 55000 | M47: 0.05 | N47: UPI | O47: Completed | P47: 46190 | Q47: 1 | R47: New | S47: Call before delivery | T47: =K47*L47 -> 275000 | U47: =T47*M47 -> 13750 | V47: =T47-U47 -> 261250
A48: ORD-1047 | B48: 46202 | C48: Yash Borse | D48: Female | E48: 31 | F48: Delhi | G48: Delhi | H48: Accessories | I48: Headphones | J48: Rajesh Khan | K48: 6 | L48: 2200 | M48: 0.1 | N48: Cash | O48: Completed | P48: 46205 | Q48: 3 | R48: Returning | S48: Call before delivery | T48: =K48*L48 -> 13200 | U48: =T48*M48 -> 1320 | V48: =T48-U48 -> 11880
A49: ORD-1048 | B49: 46206 | C49: Rohan Joshi | D49: Male | E49: 27 | F49: Hyderabad | G49: Telangana | H49: Office Supplies | I49: Printer Paper | J49: Rajesh Khan | K49: 4 | L49: 320 | M49: 0.2 | N49: Cash | O49: Completed | P49: 46208 | Q49: 4 | R49: Returning | S49: Prompt delivery requested | T49: =K49*L49 -> 1280 | U49: =T49*M49 -> 256 | V49: =T49-U49 -> 1024
A50: ORD-1049 | B50: 46152 | C50: Devansh More | D50: Male | E50: 47 | F50: Dhule | G50: Maharashtra | H50: Electronics | I50: Monitor | J50: Rahul Verma | K50: 21 | L50: 14500 | M50: 0.15 | N50: UPI | O50: Completed | P50: 46158 | Q50: 5 | R50: Returning | S50: Standard packing | T50: =K50*L50 -> 304500 | U50: =T50*M50 -> 45675 | V50: =T50-U50 -> 258825
A51: ORD-1050 | B51: 46229 | C51: Yash Borse | D51: Female | E51: 50 | F51: Jalgaon | G51: Maharashtra | H51: Accessories | I51: USB Cable | J51: Rahul Verma | K51: 11 | L51: 250 | M51: 0.05 | N51: Cash | O51: Completed | P51: 46234 | Q51: 4 | R51: New | S51: Follow up needed | T51: =K51*L51 -> 2750 | U51: =T51*M51 -> 137.5 | V51: =T51-U51 -> 2612.5
A52: ORD-1051 | B52: 46141 | C52: Aadhya Thorat | D52: Female | E52: 42 | F52: Malegaon | G52: Maharashtra | H52: Office Supplies | I52: File Folder | J52: Priya Patel | K52: 16 | L52: 85 | M52: 0.05 | N52: Credit Card | O52: Pending | P52: 46146 | Q52: 3 | R52: Returning | S52: Standard packing | T52: =K52*L52 -> 1360 | U52: =T52*M52 -> 68 | V52: =T52-U52 -> 1292
A53: ORD-1052 | B53: 46202 | C53: Anaya Kamble | D53: Male | E53: 54 | F53: Pune | G53: Maharashtra | H53: Electronics | I53: Keyboard | J53: Neha Gupta | K53: 14 | L53: 1200 | M53: 0.15 | N53: Net Banking | O53: Pending | P53: 46205 | Q53: 4 | R53: Returning | S53: Call before delivery | T53: =K53*L53 -> 16800 | U53: =T53*M53 -> 2520 | V53: =T53-U53 -> 14280
A54: ORD-1053 | B54: 46225 | C54: Rohan Joshi | D54: Female | E54: 35 | F54: Jalgaon | G54: Maharashtra | H54: Accessories | I54: Webcam | J54: Rahul Verma | K54: 22 | L54: 3500 | M54: 0.2 | N54: Credit Card | O54: Completed | P54: 46226 | Q54: 5 | R54: Returning | S54: Call before delivery | T54: =K54*L54 -> 77000 | U54: =T54*M54 -> 15400 | V54: =T54-U54 -> 61600
...

Sheet Data_Entry
B2: Customer Order Entry Form
B3: Fill in the parameters below. Data validation rules ensure accurate input.
B5: Order ID | D5: (Auto-generated (e.g. ORD-1101))
B6: Order Date | D6: (=TODAY())
B7: Customer Name | D7: (Enter full name)
B8: Gender | D8: (Select from drop-down)
B9: Age | D9: (Enter age (18 - 80))
B10: City | D10: (Select City)
B11: State | D11: (Select State)
B12: Product Category | D12: (Select Category)
B13: Product | D13: (Enter Product Name)
B14: Salesperson | D14: (Select Salesperson)
B15: Quantity | D15: (Enter whole number (1 - 100))
B16: Unit Price (₹) | D16: (Enter unit price)
... B21: Rating | D21: (Enter rating (1 - 5))

Sheet Series_Practice
A1: Excel Series & AutoFill Exercises
A3: Number Series (1,2,3...) | C3: Even Numbers (2,4,6...) | E3: Odd Numbers (1,3,5...) | G3: Daily Date Series | I3: Weekday Series | K3: Month Series | M3: Month-Year Series | O3: Custom List Series

Sheet Analysis
A1: Key Performance Metrics & Practical Analysis
A3: 1. Overall Dataset Summary (Mathematical Functions) | D3: 2. Order Status Breakdown
A4: Metric Description | B4: Formula / Value | D4: Order Status | E4: Order Count (COUNTIF) | F4: Net Sales (SUMIF)
A5: Total Quantity Sold | D5: Completed
A6: Total Sales Amount (Gross) | D6: Pending
A7: Total Discount Amount | D7: Cancelled
A8: Net Revenue / Net Sales
A9: Average Unit Price
A10: Highest Unit Price | D10: 3. Sales Performance by Category
A11: Lowest Unit Price | D11: Category | E11: Total Net Sales | F11: Average Rating
A12: Average Discount % | D12: Electronics
A13: Total Orders Count | D13: Office Supplies
D14: Accessories
A18: 4. Practical Business Questions and Answers
A19: Metric Description | B19: Formula / Value | C19: Formula / Value
A20: Average Order Value
A21: New Vs Returning Customer Count
A22: Average Delivery Time

Sheet Date_Practice
A1: Date & Time Functions Exercises
A3: Order_ID | B3: Order_Date | C3: Delivery_Date | D3: Order_Year | E3: Order_Month | F3: Order_Day | G3: Day_of_Week | H3: Week_Number | I3: Delivery_Duration_Days | J3: End_of_Month_Date
A4: =Sales_Data!A2 -> ORD-1001 | B4: =Sales_Data!B2 -> 46186 | C4: =Sales_Data!P2 -> 46187
A5: =Sales_Data!A3 -> ORD-1002 | B5: =Sales_Data!B3 -> 46078 | C5: =Sales_Data!P3 -> 46080
A6: =Sales_Data!A4 -> ORD-1003 | B6: =Sales_Data!B4 -> 46131 | C6: =Sales_Data!P4 -> 46134
A7: =Sales_Data!A5 -> ORD-1004 | B7: =Sales_Data!B5 -> 46034 | C7: =Sales_Data!P5 -> 46040
A8: =Sales_Data!A6 -> ORD-1005 | B8: =Sales_Data!B6 -> 46081 | C8: =Sales_Data!P6 -> 46088
A9: =Sales_Data!A7 -> ORD-1006 | B9: =Sales_Data!B7 -> 46262 | C9: =Sales_Data!P7 -> 46268
A10: =Sales_Data!A8 -> ORD-1007 | B10: =Sales_Data!B8 -> 46106 | C10: =Sales_Data!P8 -> 46113
A11: =Sales_Data!A9 -> ORD-1008 | B11: =Sales_Data!B9 -> 46150 | C11: =Sales_Data!P9 -> 46154
A12: =Sales_Data!A10 -> ORD-1009 | B12: =Sales_Data!B10 -> 46079 | C12: =Sales_Data!P10 -> 46081
A13: =Sales_Data!A11 -> ORD-1010 | B13: =Sales_Data!B11 -> 46142 | C13: =Sales_Data!P11 -> 46147
A14: =Sales_Data!A12 -> ORD-1011 | B14: =Sales_Data!B12 -> 46207 | C14: =Sales_Data!P12 -> 46213
A15: =Sales_Data!A13 -> ORD-1012 | B15: =Sales_Data!B13 -> 46222 | C15: =Sales_Data!P13 -> 46227
... A23: =Sales_Data!A21 -> ORD-1020 | B23: =Sales_Data!B21 -> 46071 | C23: =Sales_Data!P21 -> 46074

Sheet Text_Practice
A1: Text & Data Cleaning Functions Exercises
A3: Raw_Customer_Name | B3: Clean_Name (TRIM/PROPER) | C3: Name_Length (LEN) | D3: First_3_Chars (LEFT) | E3: Last_4_Digits (RIGHT) | F3: City | G3: State | H3: Full_Location (TEXTJOIN)
A4: =Sales_Data!C2 -> Aarav Shah | F4: =Sales_Data!F2 -> Pune | G4: =Sales_Data!G2 -> Maharashtra
A5: =Sales_Data!C3 -> Vivaan Gaikwad | F5: =Sales_Data!F3 -> Pune | G5: =Sales_Data!G3 -> Maharashtra
A6: =Sales_Data!C4 -> Arjun Nair | F6: =Sales_Data!F4 -> Chennai | G6: =Sales_Data!G4 -> Tamil Nadu
A7: =Sales_Data!C5 -> Reyansh Bhat | F7: =Sales_Data!F5 -> Nashik | G7: =Sales_Data!G5 -> Maharashtra
A8: =Sales_Data!C6 -> Sanya Iyer | F8: =Sales_Data!F6 -> Nashik | G8: =Sales_Data!G6 -> Maharashtra
A9: =Sales_Data!C7 -> Omkar Salunkhe | F9: =Sales_Data!F7 -> Bengaluru | G9: =Sales_Data!G7 -> Karnataka
A10: =Sales_Data!C8 -> Yash Borse | F10: =Sales_Data!F8 -> Malegaon | G10: =Sales_Data!G8 -> Maharashtra
A11: =Sales_Data!C9 -> Omkar Salunkhe | F11: =Sales_Data!F9 -> Nagpur | G11: =Sales_Data!G9 -> Maharashtra
A12: =Sales_Data!C10 -> Vivaan Gaikwad | F12: =Sales_Data!F10 -> Chennai | G12: =Sales_Data!G10 -> Tamil Nadu
A13: =Sales_Data!C11 -> Arjun Nair | F13: =Sales_Data!F11 -> Bengaluru | G13: =Sales_Data!G11 -> Karnataka
A14: =Sales_Data!C12 -> Arjun Nair | F14: =Sales_Data!F12 -> Nashik | G14: =Sales_Data!G12 -> Maharashtra
A15: =Sales_Data!C13 -> aarav shah | F15: =Sales_Data!F13 -> Malegaon | G15: =Sales_Data!G13 -> Maharashtra
... A23: =Sales_Data!C21 -> Kabir Kulkarni | F23: =Sales_Data!F21 -> Hyderabad | G23: =Sales_Data!G21 -> Telangana

Sheet Dashboard
B2: EXECUTIVE SALES & CUSTOMER MANAGEMENT DASHBOARD

Sheet Final_Challenge
A1: Final Practical Examination: Independent Student Assessment
A3: Task # & Challenge Title | B3: Instructions & Required Deliverable
A4: Challenge 1: Top 10 Orders by Net Sales | B4: Use Sort & Filter or LARGE() formula to identify the top 10 transactions by revenue.
A5: Challenge 2: Top 5 Products by Quantity | B5: Create a summary using SUMIF to determine which 5 products had the highest total unit volume.
A6: Challenge 3: Highest Sales City | B6: Use SUMIF to compare revenue across all 13 cities and identify the top performing region.
A7: Challenge 4: Monthly Revenue Trend | B7: Extract order month using Date functions and aggregate monthly sales figures.
A8: Challenge 5: Top Salesperson | B8: Calculate total net sales generated by each sales representative to crown the top performer.
A9: Challenge 6: High-Value Loyal Customer Filter | B9: Filter rows where Customer_Type = 'Returning', Rating >= 4, and Net_Sales > ₹10,000.
A10: Challenge 7: Overdue Delivery Tracking | B10: Use formula =AND(Order_Status='Pending', Delivery_Date < TODAY()) to flag delayed shipments.
A11: Challenge 8: Multi-Level Order Status Sorting | B11: Perform a custom sort: Completed (Top) -> Pending (Middle) -> Cancelled (Bottom).
A12: Challenge 9: Key Account Highlight Rule | B12: Apply Conditional Formatting formula to highlight rows where Net_Sales > ₹20,000 AND Rating >= 4.
A13: Challenge 10: Executive Summary Presentation | B13: Combine formulas and visual formatting to build an executive presentation report.
